<?xml version="1.0"?>
<robot name="fcd">
    <!-- Marco de referencia BASE  link 0 -->
    <link name="base_footprint" />
    
    <joint name="fixed_joint" type="fixed">
        <origin xyz="0.0 0.0 0.0" rpy="0.0 0.0 0.0"/>    
        <parent link="base_footprint"/>
        <child link="link_base"/>
    </joint>

    <link name="link_base">
        <visual> 
            <origin xyz="0.0 0.0 0.0"/>    
            
            <geometry>
                <box size="0.1 0.1 0.1"/>    
            </geometry>

            <material name = "black">
                <color rgba="0.0 0.0 0.0 1.0"/> 
            </material>
        </visual>

        <collision>
                <origin xyz="0.0 0.0 0.0" rpy="0.0 0.0 0.0"/>
                <geometry>
                    <box size="0.1 0.1 0.1"/>    
                </geometry> 
        </collision>

        <inertial>
            <!-- <origin xyz="0.0 0.0 0.0" rpy="0.0 0.0 0.0"/> -->
            <mass value="1.0"/>
            <inertia ixx="0.001" ixy="0.0" ixz="0.0" iyy="0.001" iyz="0.0" izz="0.001"/>
        </inertial>

    </link>
    

    <!-- Definición de ruedas -->
    <joint name="joint_wheel_1" type="continuous">
        <origin xyz="0.1 0.0 0.0" rpy="$(eval -pi/2) 0.0 0.0"/>
        <parent link="link_base"/>
        <child link="wheel_1"/>
        <axis xyz="0.0 0.0 1.0"/>
    </joint>

    <link name="wheel_1"> 
        <inertial>
            <origin xyz="0.0 0.0 0.0" rpy="0.0 0.0 0.0"/>
            <mass value="1.0"/>
            <inertia ixx="0.001" ixy="0.0" ixz="0.0" iyy="0.001" iyz="0.0" izz="0.001"/>
        </inertial>

        <visual name="">
            <origin xyz="0.0 0.0 0.0" rpy="0.0 0.0 0.0"/>
            <geometry>
                <cylinder radius="0.02" length="0.03"/>
            </geometry>
            <material name="blue">
                <color rgba="0.0 0.0 1.0 1.0"/>
            </material>
        </visual>

        <collision>
            <origin xyz="0.0 0.0 0.0" rpy="0.0 0.0 0.0"/>
            <geometry>
                <cylinder radius="0.05" length="0.03"/>
            </geometry>
        </collision>
    </link>

    
</robot>